Workbook

Sheet Leyenda
A1: Selección del microcontrolador — matriz de decisión
A2: Método: proceso de análisis de decisiones del NASA Systems Engineering Handbook (NASA/SP-2016-6105 Rev2), sección 6.8: definir criterios → identificar alternativas → analizarlas → elegir. El orden importa: fijo los umbrales y los pesos ANTES de mirar a los candidatos, para no ajustarlos al que ya me gustaba.
A4: Cómo se usa este libro, en orden
A5: 1. Requisitos | B5: Traduzco la misión a números. Cada número sale de un cálculo que puedo rehacer o de un dato de vuelo. Si cambio los datos de entrada, todo lo demás se recalcula.
A6: 2. Umbrales | B6: Filtro eliminatorio: se cumple o no se cumple. Quien falla uno queda fuera SIN puntuar. Aquí meto todo lo que no se puede compensar con otra cosa.
A7: 3. Pesos | B7: Solo para los que sobreviven al filtro. El peso no lo pongo a ojo: sale de la severidad del fallo que ese criterio evita y de si ese fallo se detecta antes de volar.
A8: 4. Escala | B8: Qué significa un 1 y qué significa un 5 en cada criterio, en términos medibles. Lo defino antes de puntuar para no ajustar la escala al candidato que ya me gusta.
A9: 5. Matriz | B9: Puntúo de 1 a 5 con el dato de cada ficha técnica y sale la puntuación ponderada.
A10: 6. Sensibilidad | B10: La prueba que hace defendible la decisión: ¿gana el mismo si muevo los pesos, si los igualo o si quito un criterio? Si sí, la decisión no depende de mi opinión.
A12: Código de color
A13: Fondo amarillo | B13: Celda que relleno yo. Es donde vive mi criterio de ingeniería.
A14: Fondo crema | B14: Ejemplo de referencia (columna STM32F411RE). Verifico cada dato en la ficha técnica antes de citarlo.
A15: Texto azul | B15: Dato de entrada que decido yo (un umbral, una hipótesis de cálculo).
A16: Texto negro | B16: Fórmula. No la toques: se recalcula sola.
A17: Texto verde | B17: Enlace a otra hoja de este mismo libro.
A19: Etiqueta de evidencia (para la entrevista)
A20: Etiqueta | B20: Qué es | C20: Cómo lo defiendes | D20: Su punto débil
A21: Fuente | B21: Ficha técnica, nota de aplicación, norma o artículo. | C21: Cito el documento y la página. | D21: Las cifras del fabricante son en condiciones ideales: leo las condiciones de medida.
A22: Vuelo | B22: Algo que pasó en un vuelo o una competición reales. | C22: Ocurrió de verdad, con informe público. | D22: Era otro cohete: tengo que argumentar por qué me aplica a mí.
A23: Cálculo | B23: Un número que puedes rehacer en la pizarra. | C23: Lo repito delante del entrevistador. | D23: Solo vale si las hipótesis son buenas; las enuncio.
A24: Criterio propio | B24: Razonamiento de ingeniería sin una fuente única. Los pesos de este libro son de este tipo. | C24: Explico el razonamiento y qué pasaría si lo cambio. | D24: Es opinión: no lo presento nunca como si fuera una fuente.
A26: Los pesos, los umbrales y las notas de este libro son míos y son lo más discutible del análisis. Lo que defiendo no es cada número, es el razonamiento que hay detrás y el hecho de haber comprobado cuánto depende la decisión de ellos.

Sheet Inventario
A1: Paso 0 — Inventario de dispositivos
A2: Esta hoja va ANTES que los umbrales: la cuenta de buses no sale del catálogo del micro, sale de lo que cuelga de él. El método que sigo: primero qué estados tengo que estimar, qué eventos tengo que detectar y qué salud tengo que vigilar; de ahí salen los sensores, y de los sensores, los buses.
A4: Para qué lo necesito | B4: Componente elegido | C4: Cant. | D4: Por qué ese componente y esa cantidad | E4: Interfaz | F4: Bytes/lectura | G4: Frec. (Hz) | H4: Ancho de banda (kbit/s) | I4: Etiqueta
A5: ESTIMAR ESTADOS (el filtro de Kalman)
A6: Actitud y aceleración en las tres fases del vuelo | B6: IMU 6 ejes ICM-42686-P | C6: 1 | D6: Descarto el MPU6050, con el que ya he trabajado, por sus limitaciones. Frente al ICM-42688-P, que es el que más usan los equipos de cohetería, el 42686-P dobla los límites programables: ±32 g y ±4.000 °/s, y eso me quita una saturación en la fase de empuje. Pongo una y no dos: la duplicación se exige en EuRoC y en la America Cup, pero aquí no me obliga el reglamento, y entre la electrónica comercial redundante y el resto de sensores ya tengo con qué contrastar la medida. | E6: SPI | F6: 14 | G6: 1000 | H6: =IF(OR(F6=0,G6=0),0,C6*F6*8*G6/1000) -> 112 | I6: Criterio propio
A7: Aceleración durante la combustión sin saturar | B7: Acelerómetro de alta g H3LIS200DL (±200 g) | C7: 1 | D7: La IMU satura en ±32 g y el empuje da decenas. ST especifica este integrado para detección de choques y vibraciones extremas hasta ±200 g, y aguanta hasta 10.000 g sin destruirse. Es de 8 bits: lo quiero para la fase que satura a la IMU, no para precisión. | E7: SPI | F7: 6 | G7: 1000 | H7: =IF(OR(F7=0,G7=0),0,C7*F7*8*G7/1000) -> 48 | I7: Fuente
A8: Velocidad de alabeo tras el apagado sin saturar | B8: Giróscopo de alto rango ADXRS649 (±20.000 °/s) | C8: 1 | D8: Casi toda IMU MEMS topa en ±2.000 °/s, unas 333 rpm: si el cohete gira más tras el apagado pierdo la actitud justo cuando la necesito. Salida analógica, así que me gasta un canal de ADC y no un bus, y leyéndolo por DMA no me cuesta CPU. | E8: ADC | F8: 2 | G8: 1000 | H8: =IF(OR(F8=0,G8=0),0,C8*F8*8*G8/1000) -> 16 | I8: Fuente
A9: Referencia de rumbo (deriva del giróscopo en guiñada) | B9: Magnetómetro 3 ejes RM3100 | C9: 1 | D9: Sin GNSS ni magnetómetro el error de guiñada crece sin nada que lo ate. Elijo el RM3100 sobre el MMC5983MA porque deriva menos con la temperatura. Lo calibro con la IMU ya montada en su estructura final: el cartucho de CO2 de acero mete error de hierro duro. | E9: SPI | F9: 9 | G9: 100 | H9: =IF(OR(F9=0,G9=0),0,C9*F9*8*G9/1000) -> 7.2 | I9: Vuelo
A10: Altitud por debajo de unos 30 km | B10: Barómetro MS5607 | C10: 2 | D10: El MS5607 es el estándar de facto en cohetería; el BMP390 va mejor de consumo y de ruido y lo dejo anotado como alternativa. Pongo dos: uno en mi ordenador y otro en la electrónica de recuperación redundante. El segundo no cuelga de mi I2C, pero lo dejo en el inventario porque es el que me da la segunda opinión de apogeo. Por encima de 31 km ninguno de los dos sirve. | E10: I2C | F10: 6 | G10: 100 | H10: =IF(OR(F10=0,G10=0),0,C10*F10*8*G10/1000) -> 9.6 | I10: Fuente
A11: Temperatura ambiente para la ecuación barométrica y el sesgo del giróscopo | B11: Integrado en el barómetro y en la IMU | C11: 0 | D11: No compro nada: ya viene dentro. Pero tengo que usarlo, porque el sesgo del giróscopo deriva con la temperatura y es el error dominante del INS en un vuelo de 12 min. | E11: — | F11: 0 | G11: 0 | H11: =IF(OR(F11=0,G11=0),0,C11*F11*8*G11/1000) -> 0 | I11: Criterio propio
A12: Posición y velocidad absolutas cuando se puede | B12: GNSS de alta dinámica (u-blox, modo Airborne <4 g) | C12: 1 | D12: Se me va a bloquear por los límites COCOM durante el ascenso. Lo trato como una ayuda intermitente del filtro, no como la fuente de verdad. | E12: UART | F12: 100 | G12: 10 | H12: =IF(OR(F12=0,G12=0),0,C12*F12*8*G12/1000) -> 8 | I12: Fuente
A13: DETECTAR EVENTOS
A14: Saber que la carga de recuperación ha disparado de verdad | B14: Medida de continuidad de cerilla (divisor + ADC) | C14: 4 | D14: 2 canales por evento, drogue y principal, porque EuRoC exige recuperación redundante. Antes del vuelo me dice si la cerilla está conectada; después, si ha disparado. | E14: ADC | F14: 2 | G14: 10 | H14: =IF(OR(F14=0,G14=0),0,C14*F14*8*G14/1000) -> 0.64 | I14: Fuente
A15: Saber que algo se ha separado FÍSICAMENTE | B15: Breakwire o microinterruptor de separación | C15: 2 | D15: El que más se olvida y el que más me habría servido: distingue «he disparado la carga» de «se ha abierto». Un fallo de recuperación por un nudo en la cuerda del principal se ve aquí y no en la continuidad. | E15: GPIO | F15: 0 | G15: 0 | H15: =IF(OR(F15=0,G15=0),0,C15*F15*8*G15/1000) -> 0 | I15: Vuelo
A16: Armar el sistema desde fuera del cohete en rampa | B16: Interruptor de armado externo / pull-pin | C16: 1 | D16: Requisito de seguridad de competición: se arma con el cohete ya en rampa, sin abrirlo. Si no lo preveo en el diseño mecánico, no paso la revisión. | E16: GPIO | F16: 0 | G16: 0 | H16: =IF(OR(F16=0,G16=0),0,C16*F16*8*G16/1000) -> 0 | I16: Fuente
A17: Saber en qué posición está realmente el aerofreno | B17: Encoder o potenciómetro de posición | C17: 1 | D17: Lazo cerrado. Un servo que dice estar a 30° y no lo está me arruina el control de apogeo y no me entero. Va en el nodo de la otra bahía; lo dejo contado en mi ADC hasta que cierre el reparto de bahías. | E17: ADC | F17: 2 | G17: 100 | H17: =IF(OR(F17=0,G17=0),0,C17*F17*8*G17/1000) -> 1.6 | I17: Criterio propio
A18: Detectar que el aerofreno se ha atascado | B18: Medida de corriente del servo (shunt o INA) | C18: 1 | D18: Un pico de corriente sostenido es un atasco. Sin esto, el actuador falla en silencio. Mismo caso que el encoder: nodo del aerofreno, contado aquí por prudencia. | E18: ADC | F18: 2 | G18: 100 | H18: =IF(OR(F18=0,G18=0),0,C18*F18*8*G18/1000) -> 1.6 | I18: Criterio propio
A19: VIGILAR LA SALUD DEL SISTEMA
A20: Cuánta batería queda tras horas en rampa | B20: Monitor de tensión y corriente INA226 | C20: 2 | D20: Los LiPo descargan en meseta: mantienen la tensión durante casi toda su capacidad y caen en picado al final. Con 6 h en rampa, mirar solo la tensión me diría que la batería está llena hasta cinco minutos antes de apagarse, así que cuento culombios integrando corriente. Uno por batería, vuelo y recuperación. | E20: I2C | F20: 4 | G20: 10 | H20: =IF(OR(F20=0,G20=0),0,C20*F20*8*G20/1000) -> 0.64 | I20: Fuente
A21: Respaldo analógico del estado de batería | B21: Divisor de tensión a ADC | C21: 2 | D21: Si se me cae el bus I2C me quedo sin saber la batería. El divisor no depende de ningún bus. | E21: ADC | F21: 2 | G21: 1 | H21: =IF(OR(F21=0,G21=0),0,C21*F21*8*G21/1000) -> 0.032 | I21: Criterio propio
A22: Temperatura de la batería (seguridad del LiPo) | B22: Termistor NTC | C22: 2 | D22: Un LiPo fuera de rango de temperatura es un riesgo, y la capacidad cae con el frío en altura. | E22: ADC | F22: 2 | G22: 1 | H22: =IF(OR(F22=0,G22=0),0,C22*F22*8*G22/1000) -> 0.032 | I22: Criterio propio
A23: Temperatura de la electrónica | B23: LM75B o el sensor interno del micro | C23: 1 | D23: Verifica en vuelo el rango industrial de −40 a 85 °C que he puesto como umbral. | E23: I2C | F23: 2 | G23: 1 | H23: =IF(OR(F23=0,G23=0),0,C23*F23*8*G23/1000) -> 0.016 | I23: Criterio propio
A24: REGISTRAR Y COMUNICAR
A25: Guardar el vuelo entero sin quedarme sin sitio | B25: Flash NOR por QSPI | C25: 1 | D25: Descarto la microSD: su controladora interna mete latencias impredecibles y el sistema de ficheros FAT32 se corrompe con vibración. La flash NOR la escribo por bloques y con DMA. La dimensiono con el cálculo de la hoja Requisitos: 18,4 MB. El altímetro de respaldo de USC se quedó sin memoria a los 375 s de un vuelo de 754 s. | E25: QSPI/SDMMC | F25: 64 | G25: 200 | H25: =IF(OR(F25=0,G25=0),0,C25*F25*8*G25/1000) -> 102.4 | I25: Vuelo + Cálculo
A26: Telemetría en tiempo real | B26: Par de Matek mR900-30 con mLRS, 868 MHz | C26: 1 | D26: La antena va obligatoriamente en una sección de fibra de vidrio o en la ojiva: el carbono es opaco a RF. Con 868 MHz y más de 150 km de enlace tengo que contar con unos 135 dB de pérdidas y con el Doppler. | E26: UART | F26: 64 | G26: 10 | H26: =IF(OR(F26=0,G26=0),0,C26*F26*8*G26/1000) -> 5.12 | I26: Fuente
A27: Depurar y volcar datos en tierra | B27: Consola serie | C27: 1 | D27: Una UART dedicada. No la comparto con la radio: cuando falle la radio es cuando querré la consola. | E27: UART | F27: 0 | G27: 0 | H27: =IF(OR(F27=0,G27=0),0,C27*F27*8*G27/1000) -> 0 | I27: Criterio propio
A28: Base de tiempo del filtro | B28: TCXO + señal PPS del GNSS | C28: 1 | D28: Es el dt de mi Kalman. El PPS entra por captura de timer y me disciplina el reloj. El contador de 32 bits en µs da la vuelta cada 71,6 min, así que en 6 h de rampa da cinco vueltas antes de despegar y lo tengo que gestionar en firmware. | E28: Timer | F28: 0 | G28: 0 | H28: =IF(OR(F28=0,G28=0),0,C28*F28*8*G28/1000) -> 0 | I28: Cálculo
A29: Hablar con la bahía del aerofreno | B29: Bus CAN entre bahías | C29: 1 | D29: Cablear sensores sueltos entre bahías es peor que un bus. Me queda por definir la tabla de mensajes: identificador, contenido, frecuencia y qué hago si ese nodo muere. | E29: CAN | F29: 8 | G29: 100 | H29: =IF(OR(F29=0,G29=0),0,C29*F29*8*G29/1000) -> 6.4 | I29: Criterio propio
A30: Avisar de dónde ha caído / estado en rampa | B30: Zumbador | C30: 1 | D30: Lo agradeceré buscando el cohete en el campo, y me sirve para comprobar el armado en rampa. | E30: PWM | F30: 0 | G30: 0 | H30: =IF(OR(F30=0,G30=0),0,C30*F30*8*G30/1000) -> 0 | I30: Criterio propio
A31: Mover el aerofreno | B31: Servo | C31: 1 | D31: Viene del ejercicio de Hardware. Va en el nodo de la otra bahía, no en mi placa. | E31: PWM | F31: 0 | G31: 0 | H31: =IF(OR(F31=0,G31=0),0,C31*F31*8*G31/1000) -> 0 | I31: Criterio propio
A32: INDEPENDIENTES (no cuelgan de tu micro)
A33: Recuperación redundante exigida por la competición | B33: Electrónica comercial (p. ej. CATS Vega) con batería propia | C33: 1 | D33: Guía de EuRoC 3.3 y 3.4.1: recuperación redundante y al menos una comercial. No es opcional, y además me da un tercer voto de apogeo y datos con los que contrastar los míos. | E33: Ninguna | F33: 0 | G33: 0 | H33: =IF(OR(F33=0,G33=0),0,C33*F33*8*G33/1000) -> 0 | I33: Fuente
A34: Encontrar el cohete después de aterrizar | B34: Localizador independiente con su propia batería y radio | C34: 1 | D34: Si mi ordenador muere, el cohete sigue en algún sitio. Este no depende de nada mío. | E34: Ninguna | F34: 0 | G34: 0 | H34: =IF(OR(F34=0,G34=0),0,C34*F34*8*G34/1000) -> 0 | I34: Criterio propio
A36: Tráfico total de lectura de sensores (kbit/s) | H36: =SUM(H6:H34) -> 319.28
A37: Para comparar: un solo bus SPI a 10 MHz mueve 10.000 kbit/s, así que todo esto junto ocupa un 3 % de UN bus. La conclusión que defiendo: no separo los buses por ancho de banda, los separo por latencia y por aislamiento de fallos.
A39: De dispositivos a buses (esto es lo que le pides al micro)
A40: Recurso del micro | B40: Dispositivos que lo usan | C40: Buses/canales que pido | D40: Reserva | E40: TOTAL exigido | F40: Por qué ese reparto
A41: SPI | B41: =SUMIF($E$6:$E$34,"SPI",$C$6:$C$34) -> 3 | C41: 2 | D41: 1 | E41: =C41+D41 -> 3 | F41: SPI1 solo para la IMU, para que nada le meta latencia en el lazo del filtro. SPI2 para el acelerómetro de alta g y el magnetómetro, que no compiten con ella. La memoria de registro ya no gasta SPI porque la he puesto en QSPI, así que con 2 buses me basta y pido 1 de reserva. Es el mismo criterio de reparto que sigue el CATS Vega.
A42: UART / USART | B42: =SUMIF($E$6:$E$34,"UART",$C$6:$C$34) -> 3 | C42: 3 | D42: 1 | E42: =C42+D42 -> 4 | F42: Punto a punto: cada dispositivo pide la suya. GNSS, radio y consola de depuración, más una de reserva porque es lo primero que se me queda corto si añado un nodo.
A43: I2C | B43: =SUMIF($E$6:$E$34,"I2C",$C$6:$C$34) -> 5 | C43: 1 | D43: 1 | E43: =C43+D43 -> 2 | F43: Caben todos en un bus con direcciones distintas. Cuento los dos barómetros aunque el segundo vaya en la electrónica redundante: si acabo poniéndolo en mi placa ya está contado. Tengo que vigilar el choque de direcciones, porque muchos de estos sensores solo ofrecen dos, y los 400 pF de la especificación.
...

Sheet Requisitos
A1: Paso 1 — De la misión a los números
A2: Cada requisito del micro sale de la misión, no del catálogo. Si cambio los datos de entrada (azul), los requisitos se recalculan solos.
A4: Datos de entrada (los decides tú)
A5: Parámetro | B5: Valor | C5: Unidad | D5: De dónde sale | E5: Etiqueta
A6: Duración del vuelo de referencia | B6: 754 | C6: s | D6: Aftershock II (USC) aterrizó a T+754 s. | E6: Vuelo
A7: Margen sobre la duración de vuelo | B7: 1 | C7: × | D7: El vuelo real puede durar más que el simulado. Me dejo un margen del 100 %. | E7: Criterio propio
A8: Espera mínima en rampa | B8: 6 | C8: h | D8: Guía de EuRoC, apartado 3.4: autonomía mínima en rampa. | E8: Fuente
A9: Estados del filtro de Kalman (n) | B9: 15 | C9: estados | D9: USC usó 15 estados (en MATLAB, post-vuelo). CATS Vega usa 3 a bordo. | E9: Vuelo
A10: Frecuencia del filtro | B10: 200 | C10: Hz | D10: Objetivo de diseño mío. El CATS Vega corre a 100 Hz. | E10: Criterio propio
A11: Coste del filtro por paso | B11: 6 | C11: × n³ ops | D11: Estimación del coste de propagar la covarianza (O(n³)). | E11: Criterio propio
A12: Ciclos por operación en coma flotante | B12: 4 | C12: ciclos | D12: Incluyo accesos a memoria y bucle, no solo la instrucción de la FPU. | E12: Criterio propio
A13: Bytes por muestra de registro | B13: 64 | C13: bytes | D13: Estimación mía de la trama de telemetría y registro. | E13: Criterio propio
A14: Frecuencia de registro | B14: 200 | C14: Hz | D14: Objetivo de diseño mío. | E14: Criterio propio
A15: Escala de posición en ECEF | B15: 6400000 | C15: m | D15: Radio terrestre aproximado. | E15: Cálculo
A17: Requisitos que salen de esos datos
A18: Requisito | B18: Valor | C18: Unidad | D18: Cómo se obtiene | E18: Etiqueta
A19: Duración de misión de diseño (registro y energía) | B19: =B6*(1+B7) -> 1508 | C19: s | D19: Duración de vuelo × (1 + margen). | E19: Cálculo
A20: Memoria de registro necesaria | B20: =B13*B14*B19/1048576 -> 18.408203 | C20: MB | D20: bytes/muestra × Hz × duración de diseño. El altímetro de respaldo de USC se quedó sin memoria a los 375 s de un vuelo de 754 s: por eso lo dimensiono con margen. | E20: Cálculo + Vuelo
A21: Operaciones en coma flotante por paso del filtro | B21: =B11*B9^3 -> 20250 | C21: ops | D21: Coste por paso ≈ 6·n³. | E21: Cálculo
A22: Carga de cálculo del filtro | B22: =B21*B10/1000000 -> 4.05 | C22: Mops/s | D22: ops por paso × frecuencia del filtro. | E22: Cálculo
A23: Ciclos de CPU por segundo que consume el filtro | B23: =B22*B12 -> 16.2 | C23: Mciclos/s | D23: Mops/s × ciclos por operación. Lo comparo con los MHz del candidato: eso es el % de CPU. | E23: Cálculo
A24: Resolución de un float de 32 bits a escala ECEF | B24: =2^(INT(LOG(B15,2))-23) -> 0.5 | C24: m | D24: Mantisa de 24 bits: entre 2^22 y 2^23 los valores van de 0,5 en 0,5. O uso FPU de doble precisión o trabajo en un marco local ENU. | E24: Cálculo
A25: Vuelta del contador de microsegundos de 32 bits | B25: =2^32/1000000/60 -> 71.582788 | C25: min | D25: 2^32 µs. Con 6 h en rampa da la vuelta varias veces antes del despegue, así que lo gestiono en firmware. | E25: Cálculo
A26: Vueltas del contador durante la espera en rampa | B26: =B8*60/B25 -> 5.0291419 | C26: vueltas | D26: Horas en rampa × 60 / minutos por vuelta. | E26: Cálculo
A27: Rango de temperatura exigido | B27: −40 a 85 °C | C27: °C | D27: Rango industrial. Es el sufijo del número de pieza, no el de la familia. | E27: Fuente
A29: Este resultado es el que leo antes de poner los pesos: los ciclos que consume mi filtro son una fracción pequeña de los MHz de todos los candidatos, así que la potencia de cálculo NO distingue entre ellos y no merece un peso alto. Lo mido en una Nucleo en cuanto la tenga, en vez de suponerlo: esa medida es lo que puedo enseñar en la entrevista.

Sheet Umbrales
A1: Paso 2 — Filtro de umbrales (eliminatorio)
A2: Un umbral no se puntúa: se cumple o no. Quien falla uno queda fuera, por muy bien que esté en lo demás. Es lo que impide que un micro barato me compense con el precio una carencia que me tira el cohete.
A4: Umbral | B4: Mínimo exigido | C4: STM32F411RE | E4: STM32F446RE | G4: STM32G474RE | I4: STM32H743ZI | K4: ESP32-S3 | M4: STM32F767ZI | O4: STM32H563ZI | Q4: STM32L476RG | S4: STM32L552ZE | U4: STM32U385RG | W4: STM32U5A5ZJ | Y4: STM32C5A3ZG
C5: Dato | D5: ¿Cumple? | E5: Dato | F5: ¿Cumple? | G5: Dato | H5: ¿Cumple? | I5: Dato | J5: ¿Cumple? | K5: Dato | L5: ¿Cumple? | M5: Dato | N5: ¿Cumple? | O5: Dato | P5: ¿Cumple? | Q5: Dato | R5: ¿Cumple? | S5: Dato | T5: ¿Cumple? | U5: Dato | V5: ¿Cumple? | W5: Dato | X5: ¿Cumple? | Y5: Dato | Z5: ¿Cumple?
A6: Familia STM32 | B6: Exigido por el enunciado | C6: STM32 | D6: SÍ | E6: STM32 | F6: SÍ | G6: STM32 | H6: SÍ | I6: STM32 | J6: SÍ | K6: Xtensa LX7, no es ST | L6: NO | M6: STM32 | N6: SÍ | O6: STM32 | P6: SÍ | Q6: STM32 | R6: SÍ | S6: STM32 | T6: SÍ | U6: STM32 | V6: SÍ | W6: STM32 | X6: SÍ | Y6: STM32 | Z6: SÍ
A7: FPU en hardware | B7: Obligatoria para el filtro | C7: Cortex-M4F, simple | D7: SÍ | E7: Cortex-M4F, simple | F7: SÍ | G7: Cortex-M4F, simple | H7: SÍ | I7: Cortex-M7, doble precisión | J7: SÍ | K7: FPU simple | L7: SÍ | M7: Cortex-M7, doble precisión | N7: SÍ | O7: Cortex-M33, simple | P7: SÍ | Q7: Cortex-M4F, simple | R7: SÍ | S7: Cortex-M33, simple | T7: SÍ | U7: Cortex-M33, simple | V7: SÍ | W7: Cortex-M33, simple | X7: SÍ | Y7: Cortex-M33, simple | Z7: SÍ
A8: Buses SPI | B8: ="≥ "&Inventario!E41&" buses SPI (calculado en la hoja Inventario)" -> ≥ 3 buses SPI (calculado en la hoja Inventario) | C8: 5 | D8: SÍ | E8: 3 — justo, sin margen | F8: SÍ | G8: 3 — justo, sin margen | H8: SÍ | I8: 6 | J8: SÍ | K8: 4 (2 libres) | L8: SÍ | M8: 6 | N8: SÍ | O8: 6 | P8: SÍ | Q8: 3 — justo, sin margen | R8: SÍ | S8: 3 — justo, sin margen | T8: SÍ | U8: 3 — justo, sin margen | V8: SÍ | W8: 3 — justo, sin margen | X8: SÍ | Y8: 3 — justo, sin margen | Z8: SÍ
A9: UART / USART | B9: ="≥ "&Inventario!E42&" UART (calculado en la hoja Inventario)" -> ≥ 4 UART (calculado en la hoja Inventario) | C9: 3 — justo, sin reserva | D9: NO | E9: 6 (4 USART + 2 UART) | F9: SÍ | G9: 5 + LPUART | H9: SÍ | I9: 8 + LPUART | J9: SÍ | K9: 3 | L9: NO | M9: 8 (4 USART + 4 UART) | N9: SÍ | O9: 13 (6 USART + 7 UART) | P9: SÍ | Q9: 5 (3 USART + 2 UART) | R9: SÍ | S9: 5 | T9: SÍ | U9: 5 | V9: SÍ | W9: 7 | X9: SÍ | Y9: 7 | Z9: SÍ
A10: I2C | B10: ="≥ "&Inventario!E43&" buses I2C (calculado en la hoja Inventario)" -> ≥ 2 buses I2C (calculado en la hoja Inventario) | C10: 3 | D10: SÍ | E10: 4 | F10: SÍ | G10: 4 | H10: SÍ | I10: 4 | J10: SÍ | K10: 2 | L10: SÍ | M10: 4 | N10: SÍ | O10: 4 | P10: SÍ | Q10: 3 | R10: SÍ | S10: 4 | T10: SÍ | U10: 2 — justo | V10: SÍ | W10: 6 | X10: SÍ | Y10: 2 — justo | Z10: SÍ
A11: CAN (bxCAN o FDCAN) | B11: ="≥ "&Inventario!E44&" CAN (calculado en la hoja Inventario)" -> ≥ 1 CAN (calculado en la hoja Inventario) | C11: 0 — no tiene CAN | D11: NO | E11: 2 bxCAN | F11: SÍ | G11: 3 FDCAN | H11: SÍ | I11: 2 FDCAN | J11: SÍ | K11: 1 TWAI | L11: SÍ | M11: 3 bxCAN | N11: SÍ | O11: 2 FDCAN | P11: SÍ | Q11: 1 bxCAN — justo | R11: SÍ | S11: 1 FDCAN — justo | T11: SÍ | U11: 1 FDCAN — justo | V11: SÍ | W11: 1 FDCAN — justo | X11: SÍ | Y11: 2 FDCAN | Z11: SÍ
A12: Interfaz de registro | B12: SDMMC/SDIO o QSPI con DMA | C12: SDIO | D12: SÍ | E12: FMC + Quad SPI + SD/MMC | F12: SÍ | G12: QUADSPI, sin SD/MMC | H12: SÍ | I12: 2 SDMMC + Dual Quad SPI | J12: SÍ | K12: SDMMC + flash SPI | L12: SÍ | M12: Dual Quad SPI + SD/MMC | N12: SÍ | O12: Octo SPI + SD/MMC | P12: SÍ | Q12: FMC + Quad SPI + SD/MMC | R12: SÍ | S12: Octo SPI + SD/MMC | T12: SÍ | U12: Octo SPI + SD/MMC | V12: SÍ | W12: Dual Octo SPI, sin SD/MMC | X12: SÍ | Y12: Octo SPI, sin SD/MMC | Z12: SÍ
A13: Canales ADC | B13: ="≥ "&Inventario!E45&" canales ADC (calculado en la hoja Inventario)" -> ≥ 12 canales ADC (calculado en la hoja Inventario) | C13: 16 | D13: SÍ | E13: 16 | F13: SÍ | G13: 26 | H13: SÍ | I13: 28 | J13: SÍ | K13: 20 | L13: SÍ | M13: 24 | N13: SÍ | O13: 18 | P13: SÍ | Q13: 16 | R13: SÍ | S13: 14 | T13: SÍ | U13: 15 | V13: SÍ | W13: 22 | X13: SÍ | Y13: 28 | Z13: SÍ
A14: Timers con PWM | B14: ="≥ "&Inventario!E46&" timers con PWM (calculado en la hoja Inventario)" -> ≥ 3 timers con PWM (calculado en la hoja Inventario) | C14: 8 | D14: SÍ | E14: 14 timers | F14: SÍ | G14: 13 timers | H14: SÍ | I14: 14 timers | J14: SÍ | K14: 8 canales LEDC | L14: SÍ | M14: 14 timers | N14: SÍ | O14: 18 timers | P14: SÍ | Q14: 11 timers | R14: SÍ | S14: 11 timers | T14: SÍ | U14: 6 timers | V14: SÍ | W14: 15 timers | X14: SÍ | Y14: 12 timers | Z14: SÍ
A15: RAM | B15: ≥ requisito del filtro + buffers | C15: 128 kB | D15: SÍ | E15: 128 kB | F15: SÍ | G15: 128 kB | H15: SÍ | I15: 1 MB | J15: SÍ | K15: 512 kB | L15: SÍ | M15: 512 kB | N15: SÍ | O15: 640 kB | P15: SÍ | Q15: 128 kB | R15: SÍ | S15: 256 kB | T15: SÍ | U15: 256 kB | V15: SÍ | W15: 2,5 MB | X15: SÍ | Y15: 256 kB | Z15: SÍ
A16: Flash interna | B16: ≥ 256 kB | C16: 512 kB | D16: SÍ | E16: 512 kB | F16: SÍ | G16: 512 kB | H16: SÍ | I16: 2 MB | J16: SÍ | K16: Externa | L16: SÍ | M16: 2 MB | N16: SÍ | O16: 2 MB | P16: SÍ | Q16: 1 MB | R16: SÍ | S16: 512 kB | T16: SÍ | U16: 1 MB | V16: SÍ | W16: 4 MB | X16: SÍ | Y16: 1 MB | Z16: SÍ
A17: Temperatura | B17: −40 a 85 °C (sufijo del número de pieza) | C17: −40/105 | D17: SÍ | E17: −40/105 | F17: SÍ | G17: −40/125 | H17: SÍ | I17: −40/85 | J17: SÍ | K17: −40/85 | L17: SÍ | M17: −40/85 | N17: SÍ | O17: −40/125 | P17: SÍ | Q17: −40/125 | R17: SÍ | S17: −40/125 | T17: SÍ | U17: −40/105 | V17: SÍ | W17: −40/125 | X17: SÍ | Y17: −40/85 | Z17: SÍ
A18: Encapsulado soldable por el equipo | B18: LQFP (sin horno ni rayos X) | C18: LQFP64 | D18: SÍ | E18: LQFP64 | F18: SÍ | G18: LQFP64 | H18: SÍ | I18: LQFP144 | J18: SÍ | K18: Módulo QFN | L18: NO | M18: LQFP144 | N18: SÍ | O18: LQFP144 | P18: SÍ | Q18: LQFP64 | R18: SÍ | S18: LQFP144 | T18: SÍ | U18: LQFP64 | V18: SÍ | W18: LQFP144 | X18: SÍ | Y18: LQFP144 | Z18: SÍ
A19: Placa de evaluación disponible ya | B19: Nucleo o Discovery en stock | C19: Nucleo-F411RE | D19: SÍ | E19: Nucleo-F446RE | F19: SÍ | G19: Nucleo-G474RE | H19: SÍ | I19: Nucleo-H743ZI2 | J19: SÍ | K19: DevKitC | L19: SÍ | M19: Nucleo-F767ZI | N19: SÍ | O19: Nucleo-H563ZI | P19: SÍ | Q19: Nucleo-L476RG | R19: SÍ | S19: Nucleo-L552ZE-Q | T19: SÍ | U19: Nucleo-U385RG-Q | V19: SÍ | W19: Nucleo-U5A5ZJ-Q | X19: SÍ | Y19: Por confirmar — serie nueva | Z19: —
A20: Disponibilidad y longevidad | B20: En stock y en programa de longevidad de ST | C20: Sí | D20: SÍ | E20: Sí | F20: SÍ | G20: Sí | H20: SÍ | I20: Sí; escasez en 2021 | J20: SÍ | K20: Sí | L20: SÍ | M20: Sí | N20: SÍ | O20: Sí | P20: SÍ | Q20: Sí | R20: SÍ | S20: Sí | T20: SÍ | U20: Sí; serie de 2025 | V20: SÍ | W20: Sí | X20: SÍ | Y20: Sí; serie nueva | Z20: SÍ
A21: Todo coexiste en el encapsulado | B21: Verificado en CubeMX sin conflictos de patillas | C21: Por verificar | D21: — | E21: Por verificar | F21: — | G21: Por verificar | H21: — | I21: Por verificar | J21: — | K21: Por verificar | L21: — | M21: Por verificar | N21: — | O21: Por verificar | P21: — | Q21: Por verificar | R21: — | S21: Por verificar | T21: — | U21: Por verificar | V21: — | W21: Por verificar | X21: — | Y21: Por verificar | Z21: —
A23: VEREDICTO | B23: Basta un NO para quedar fuera | C23: =IF(COUNTIF(D6:D21,"NO")>0,"ELIMINADO","PASA") -> ELIMINADO | E23: =IF(COUNTIF(F6:F21,"NO")>0,"ELIMINADO","PASA") -> PASA | G23: =IF(COUNTIF(H6:H21,"NO")>0,"ELIMINADO","PASA") -> PASA | I23: =IF(COUNTIF(J6:J21,"NO")>0,"ELIMINADO","PASA") -> PASA | K23: =IF(COUNTIF(L6:L21,"NO")>0,"ELIMINADO","PASA") -> ELIMINADO | M23: =IF(COUNTIF(N6:N21,"NO")>0,"ELIMINADO","PASA") -> PASA | O23: =IF(COUNTIF(P6:P21,"NO")>0,"ELIMINADO","PASA") -> PASA | Q23: =IF(COUNTIF(R6:R21,"NO")>0,"ELIMINADO","PASA") -> PASA | S23: =IF(COUNTIF(T6:T21,"NO")>0,"ELIMINADO","PASA") -> PASA | U23: =IF(COUNTIF(V6:V21,"NO")>0,"ELIMINADO","PASA") -> PASA | W23: =IF(COUNTIF(X6:X21,"NO")>0,"ELIMINADO","PASA") -> PASA | Y23: =IF(COUNTIF(Z6:Z21,"NO")>0,"ELIMINADO","PASA") -> PASA
A25: Sobre el STM32F411RE: es el micro del CATS Vega, el ordenador de vuelo oficial de EuRoC, así que lo uso como referencia de «lo mínimo que basta». Aquí se me cae por dos motivos, y el de fondo es el CAN. Eso no dice que sea mal micro, dice que mi arquitectura con bus entre bahías pide CAN. El CATS resuelve lo mismo de otra forma: pone un segundo micro, un STM32G0, para la radio y el GNSS.
A27: Los candidatos no los elegí a mano. Apliqué estos 16 umbrales a las 1.644 referencias del selector paramétrico de ST: quedaron 337, repartidas en diez series (F4, L4, F7, H7, H5, G4, U5, C5, U3, L5). De ahí bajo a lista corta con una regla declarada: UN representante por serie, el que tiene placa Nucleo, porque esa es la única condición de mi lista que el selector no sabe filtrar. Más dos controles que dejo caer a propósito: el ESP32-S3, que cae por familia y por encapsulado, y el STM32F411RE, que es el micro del CATS Vega y cae por CAN y por UART. Del F4 represento con el F446RE y no con el F405RG: el F405 no tiene Nucleo propia y además le falta QUADSPI, así que por mi propia regla el representante de la serie es el F446. Dos avisos honestos: el STM32U575ZI aparece en el catálogo con 0 timers, que es un hueco de la base de datos y no de la pieza, así que represento el U5 con el U5A5ZJ; y la placa de evaluación del C5A3ZG está por confirmar, que es lo único que podría eliminarlo.

Sheet Pesos
A1: Paso 3 — De dónde salen los pesos
A2: El peso no lo pongo a ojo. Sale de dos preguntas: qué pasa en vuelo si me equivoco en este criterio (severidad) y si ese fallo se vería antes de volar (detectabilidad). Un criterio cuyo fallo se detecta en el banco pesa menos, porque tengo una segunda oportunidad de cazarlo. Es la lógica de un FMEA aplicada a la elección.
A4: Criterio | B4: Qué mide exactamente | C4: Qué pasa si me equivoco | D4: Severidad (1-5) | E4: No detectabilidad (1-5) | F4: Peso crudo | G4: Peso derivado (%) | H4: Peso final (%) | I4: Etiqueta
A5: Margen de cálculo del filtro | B5: % de CPU libre con el EKF corriendo a la frecuencia objetivo, medido en una Nucleo, no estimado. | C5: El filtro no cierra a tiempo, pierdo la estimación de actitud y no detecto el apogeo. Pierdo el cohete. | D5: 5 | E5: 2 | F5: =D5*E5 -> 10 | G5: =F5/SUM($F$5:$F$13)*100 -> 11.904762 | H5: =G5 -> 11.904762 | I5: Cálculo + Criterio propio
A6: Precisión numérica y marco de referencia | B6: FPU de doble precisión, o float con un marco local ENU justificado con el cálculo de resolución. | C6: Las covarianzas divergen en silencio. Le pasó a ArduPilot y se arregló repitiendo el cálculo en doble precisión. | D6: 5 | E6: 4 | F6: =D6*E6 -> 20 | G6: =F6/SUM($F$5:$F$13)*100 -> 23.809524 | H6: =G6 -> 23.809524 | I6: Fuente + Cálculo
A7: Margen de periféricos y patillas | B7: Buses y patillas libres POR ENCIMA del umbral, ya rutados en CubeMX. | C7: Rediseño de PCB o un sensor que se me cae del diseño. Me cuesta programa, no cohete. | D7: 3 | E7: 1 | F7: =D7*E7 -> 3 | G7: =F7/SUM($F$5:$F$13)*100 -> 3.5714286 | H7: =G7 -> 3.5714286 | I7: Criterio propio
A8: Arquitectura y ancho de banda del registro | B8: SDMMC/QSPI con DMA y memoria suficiente para la duración de misión de diseño. | C8: Me quedo sin datos a mitad de vuelo. Le pasó al altímetro de respaldo de USC a los 375 s de 754 s. | D8: 3 | E8: 3 | F8: =D8*E8 -> 9 | G8: =F8/SUM($F$5:$F$13)*100 -> 10.714286 | H8: =G8 -> 10.714286 | I8: Vuelo + Cálculo
A9: Consumo durante la espera en rampa | B9: Consumo medio × 6 h frente a mi presupuesto de batería. La rampa dimensiona la batería, no el vuelo. | C9: La batería no llega al despegue o subo masa de más. Vuelo abortado. | D9: 4 | E9: 2 | F9: =D9*E9 -> 8 | G9: =F9/SUM($F$5:$F$13)*100 -> 9.5238095 | H9: =G9 -> 9.5238095 | I9: Fuente + Cálculo
A10: Funciones de robustez | B10: ECC en RAM/Flash, watchdog independiente con ventana, sistema de seguridad de reloj (CSS), detector de caída de tensión. | C10: Un reinicio o un bit alterado en vuelo sin nada que lo cace. No se reproduce en el banco. | D10: 5 | E10: 5 | F10: =D10*E10 -> 25 | G10: =F10/SUM($F$5:$F$13)*100 -> 29.761905 | H10: =G10 -> 29.761905 | I10: Fuente
A11: Continuidad con el equipo y ecosistema | B11: ¿Lo vuela ya Faraday? ¿Reutilizo drivers? ¿Hay soporte HAL y ejemplos? | C11: Repito trabajo que el equipo ya tenía hecho y nadie sabe mantener mi placa. | D11: 2 | E11: 2 | F11: =D11*E11 -> 4 | G11: =F11/SUM($F$5:$F$13)*100 -> 4.7619048 | H11: =G11 -> 4.7619048 | I11: Criterio propio
A12: Riesgo de calendario | B12: Cuánto me cuesta arrancarlo: caché, MPU y DMA del M7 frente a un M4 que arranca directo desde CubeMX. | C12: No entrego a tiempo, o entrego algo superficial que no aguanta las preguntas. | D12: 3 | E12: 1 | F12: =D12*E12 -> 3 | G12: =F12/SUM($F$5:$F$13)*100 -> 3.5714286 | H12: =G12 -> 3.5714286 | I12: Criterio propio
A13: Coste y disponibilidad real | B13: Precio unitario, plazo de entrega y programa de longevidad. | C13: No me llega la pieza. La escasez de STM32H7 de 2021 es el precedente. | D13: 2 | E13: 1 | F13: =D13*E13 -> 2 | G13: =F13/SUM($F$5:$F$13)*100 -> 2.3809524 | H13: =G13 -> 2.3809524 | I13: Vuelo + Fuente
A14: TOTAL | F14: =SUM(F5:F13) -> 84 | G14: =SUM(G5:G13) -> 100 | H14: =SUM(H5:H13) -> 100 | I14: =IF(ROUND(H14,1)=100,"OK: suma 100","CORRIGE: debe sumar 100") -> OK: suma 100
A16: Escala de severidad que uso: 1 = molestia de proyecto · 2 = retrabajo · 3 = pierdo datos o rediseño la placa · 4 = vuelo abortado · 5 = pérdida del cohete.
A17: Escala de no detectabilidad: 1 = CubeMX me lo dice el primer día · 2 = se mide en el banco · 3 = solo aparece en un ensayo largo · 4 = solo en el perfil real de vuelo · 5 = no se reproduce en tierra.
A19: Por qué este método y no poner los pesos a ojo: me da una frase de defensa por cada peso. «La robustez pesa más que los periféricos porque un fallo de periféricos lo veo en CubeMX el primer día y un bit alterado en vuelo no lo ve nadie hasta que el cohete no abre el paracaídas.» Eso se sostiene; «me pareció más importante», no. Los números de severidad y no detectabilidad siguen siendo criterio propio.

Sheet Escala
A1: Paso 4 — Qué significa cada nota
A2: Defino esto ANTES de mirar a los candidatos. Si definiera la escala después, la estaría ajustando sin querer al que ya había elegido. Las anclas son medibles: nada de «bueno» o «suficiente».
A4: Criterio | B4: Nota 5 | C4: Nota 3 | D4: Nota 1 | E4: De dónde sacas el dato
A5: Margen de cálculo del filtro | B5: El EKF ocupa < 10 % de CPU a la frecuencia objetivo, medido con un contador de ciclos. | C5: Entre 25 % y 40 % de CPU. | D5: Más del 60 %, o no lo has medido. | E5: Contador DWT de ciclos en una placa Nucleo, con mi filtro real.
A6: Precisión numérica y marco de referencia | B6: FPU de doble precisión en hardware (Cortex-M7). | C6: Float, pero con marco local ENU y el cálculo de resolución hecho y documentado. | D6: Float en ECEF sin analizar la escala. | E6: Ficha del núcleo (ST AN4044) y mi cálculo de resolución de la hoja Requisitos.
A7: Margen de periféricos y patillas | B7: ≥ 2 buses libres de cada tipo después de rutarlo entero en CubeMX. | C7: 1 bus libre de cada tipo. | D7: Sale justo, sin reserva. | E7: Mi proyecto de CubeMX con todos los sensores del Ej. 2 asignados.
A8: Arquitectura y ancho de banda del registro | B8: SDMMC de 4 bits con DMA y ≥ 4× la memoria calculada. | C8: QSPI con 2× de margen. | D8: Solo flash interna, sin margen sobre el cálculo. | E8: Ficha técnica y el requisito de memoria de la hoja Requisitos.
A9: Consumo durante la espera en rampa | B9: ≤ 50 % del presupuesto de batería de 6 h. | C9: Entre 50 % y 80 %. | D9: Más del 100 %: no llega al despegue. | E9: Corriente por MHz de la ficha × mi reloj, y después medido en el banco.
A10: Funciones de robustez | B10: ECC en RAM y Flash + watchdog independiente con ventana + CSS + detector de caída de tensión. | C10: Watchdog y CSS, sin ECC. | D10: Solo watchdog básico. | E10: Ficha técnica y ST AN5342 (ECC).
A11: Continuidad con el equipo y ecosistema | B11: Familia que Faraday ya vuela: drivers y experiencia reutilizables. | C11: Misma familia, subfamilia distinta. | D11: Familia nueva para el equipo. | E11: Pendiente de confirmarlo con Víctor o con María. Que el equipo trabaja con STM32 lo dice el propio enunciado.
A12: Riesgo de calendario | B12: Arranca desde CubeMX sin tocar caché ni MPU. | C12: Necesita ajustes conocidos y documentados. | D12: Caché, DMA y MPU por resolver, con una semana por delante. | E12: Mi experiencia montando el proyecto base esta semana.
A13: Coste y disponibilidad real | B13: < 10 €, stock inmediato, longevidad garantizada más allá de 2030. | C13: < 25 €, plazo de semanas. | D13: > 40 € o plazo desconocido. | E13: Distribuidor (Mouser, Farnell, DigiKey) y la tabla de longevidad de ST.
A15: Las notas 2 y 4 son interpolación. Si dudo entre dos me quedo con la baja y anoto por qué: una nota prudente con motivo vale más que una generosa sin él.
A17: La trampa que me pueden buscar: no puntúo con los MHz de la portada de la ficha. «480 MHz» no es un criterio; «me deja el 92 % de la CPU libre con mi filtro a 200 Hz» sí lo es. La primera cifra la ha escrito el fabricante, la segunda la mido yo.

Sheet Matriz
A1: Paso 5 — La matriz ponderada
A2: Solo puntúo a los que han pasado el filtro de umbrales. Notas de 1 a 5 según las anclas de la hoja Escala, que definí antes de mirar las fichas. La puntuación final está normalizada de 0 a 100 para que se lea fácil.
A4: Criterio | B4: Peso (%) | C4: STM32F411RE | D4: STM32F446RE | E4: STM32G474RE | F4: STM32H743ZI | G4: ESP32-S3 | H4: STM32F767ZI | I4: STM32H563ZI | J4: STM32L476RG | K4: STM32L552ZE | L4: STM32U385RG | M4: STM32U5A5ZJ | N4: STM32C5A3ZG
A5: Margen de cálculo del filtro | B5: =Pesos!H5 -> 11.904762 | D5: 4 | E5: 4 | F5: 4 | H5: 4 | I5: 4 | J5: 4 | K5: 4 | L5: 4 | M5: 4 | N5: 4
A6: Precisión numérica y marco de referencia | B6: =Pesos!H6 -> 23.809524 | D6: 3 | E6: 3 | F6: 5 | H6: 5 | I6: 3 | J6: 3 | K6: 3 | L6: 3 | M6: 3 | N6: 3
A7: Margen de periféricos y patillas | B7: =Pesos!H7 -> 3.5714286 | D7: 2 | E7: 2 | F7: 4 | H7: 4 | I7: 4 | J7: 1 | K7: 1 | L7: 1 | M7: 1 | N7: 1
A8: Arquitectura y ancho de banda del registro | B8: =Pesos!H8 -> 10.714286 | D8: 5 | E8: 4 | F8: 5 | H8: 5 | I8: 5 | J8: 5 | K8: 5 | L8: 5 | M8: 4 | N8: 4
A9: Consumo durante la espera en rampa | B9: =Pesos!H9 -> 9.5238095 | D9: 4 | E9: 3 | F9: 2 | H9: 3 | I9: 4 | J9: 5 | K9: 5 | L9: 5 | M9: 5 | N9: 5
A10: Funciones de robustez | B10: =Pesos!H10 -> 29.761905 | D10: 3 | E10: 4 | F10: 5 | H10: 3 | I10: 5 | J10: 3 | K10: 3 | L10: 4 | M10: 5 | N10: 4
A11: Continuidad con el equipo y ecosistema | B11: =Pesos!H11 -> 4.7619048 | D11: 3 | E11: 3 | F11: 3 | H11: 3 | I11: 3 | J11: 3 | K11: 3 | L11: 3 | M11: 3 | N11: 3
A12: Riesgo de calendario | B12: =Pesos!H12 -> 3.5714286 | D12: 5 | E12: 5 | F12: 2 | H12: 2 | I12: 4 | J12: 5 | K12: 4 | L12: 3 | M12: 4 | N12: 2
A13: Coste y disponibilidad real | B13: =Pesos!H13 -> 2.3809524 | D13: 5 | E13: 5 | F13: 3 | H13: 3 | I13: 4 | J13: 5 | K13: 4 | L13: 5 | M13: 3 | N13: 3
A15: Suma ponderada (0-100) | C15: =IF(COUNT(C5:C13)=0,"",SUMPRODUCT($B$5:$B$13,C5:C13)/5) | D15: =IF(COUNT(D5:D13)=0,"",SUMPRODUCT($B$5:$B$13,D5:D13)/5) -> 70.238095 | E15: =IF(COUNT(E5:E13)=0,"",SUMPRODUCT($B$5:$B$13,E5:E13)/5) -> 72.142857 | F15: =IF(COUNT(F5:F13)=0,"",SUMPRODUCT($B$5:$B$13,F5:F13)/5) -> 86.190476 | G15: =IF(COUNT(G5:G13)=0,"",SUMPRODUCT($B$5:$B$13,G5:G13)/5) | H15: =IF(COUNT(H5:H13)=0,"",SUMPRODUCT($B$5:$B$13,H5:H13)/5) -> 76.190476 | I15: =IF(COUNT(I5:I13)=0,"",SUMPRODUCT($B$5:$B$13,I5:I13)/5) -> 82.380952 | J15: =IF(COUNT(J5:J13)=0,"",SUMPRODUCT($B$5:$B$13,J5:J13)/5) -> 71.428571 | ... N15: =IF(COUNT(N5:N13)=0,"",SUMPRODUCT($B$5:$B$13,N5:N13)/5) -> 72.142857
A16: ¿Pasa el filtro de umbrales? | C16: =Umbrales!C23 -> ELIMINADO | D16: =Umbrales!E23 -> PASA | E16: =Umbrales!G23 -> PASA | F16: =Umbrales!I23 -> PASA | G16: =Umbrales!K23 -> ELIMINADO | H16: =Umbrales!M23 -> PASA | I16: =Umbrales!O23 -> PASA | J16: =Umbrales!Q23 -> PASA | K16: =Umbrales!S23 -> PASA | L16: =Umbrales!U23 -> PASA | M16: =Umbrales!W23 -> PASA | N16: =Umbrales!Y23 -> PASA
A17: PUNTUACIÓN FINAL | C17: =IF(AND(C16="PASA",ISNUMBER(C15)),C15,"") | D17: =IF(AND(D16="PASA",ISNUMBER(D15)),D15,"") -> 70.238095 | E17: =IF(AND(E16="PASA",ISNUMBER(E15)),E15,"") -> 72.142857 | F17: =IF(AND(F16="PASA",ISNUMBER(F15)),F15,"") -> 86.190476 | G17: =IF(AND(G16="PASA",ISNUMBER(G15)),G15,"") | H17: =IF(AND(H16="PASA",ISNUMBER(H15)),H15,"") -> 76.190476 | I17: =IF(AND(I16="PASA",ISNUMBER(I15)),I15,"") -> 82.380952 | J17: =IF(AND(J16="PASA",ISNUMBER(J15)),J15,"") -> 71.428571 | ... N17: =IF(AND(N16="PASA",ISNUMBER(N15)),N15,"") -> 72.142857
A18: Ranking | C18: =IFERROR(RANK(C17,$C$17:$N$17,0),"—") -> — | D18: =IFERROR(RANK(D17,$C$17:$N$17,0),"—") -> 9 | E18: =IFERROR(RANK(E17,$C$17:$N$17,0),"—") -> 6 | F18: =IFERROR(RANK(F17,$C$17:$N$17,0),"—") -> 1 | G18: =IFERROR(RANK(G17,$C$17:$N$17,0),"—") -> — | H18: =IFERROR(RANK(H17,$C$17:$N$17,0),"—") -> 4 | I18: =IFERROR(RANK(I17,$C$17:$N$17,0),"—") -> 2 | J18: =IFERROR(RANK(J17,$C$17:$N$17,0),"—") -> 8 | ... N18: =IFERROR(RANK(N17,$C$17:$N$17,0),"—") -> 6
A20: Ganador | B20: =IFERROR(INDEX($C$4:$N$4,MATCH(MAX($C$17:$N$17),$C$17:$N$17,0)),"faltan notas") -> STM32H743ZI
A21: Margen sobre el segundo | B21: =IFERROR(MAX($C$17:$N$17)-LARGE($C$17:$N$17,2),"—") -> 3.8095238
A22: =IF(ISNUMBER(B21),IF(B21<5,"Margen menor de 5 puntos: es un empate técnico. No presumas de ganador; decide con un criterio de desempate declarado (continuidad con el equipo o riesgo de calendario) y dilo así.","Margen suficiente para sostener la elección."),"") -> Margen menor de 5 puntos: es un empate técnico. No presumas de ganador; decide con un criterio de desempate declarado (continuidad con el equipo o riesgo de calendario) y dilo así.
A24: Cómo redacto la decisión: «Los candidatos salen de aplicar mis 16 umbrales a las 1.644 referencias del catálogo de ST: quedaron 337 en diez series, y bajé a diez candidatos con una regla declarada, uno por serie. Gana el STM32H743ZI con 86,2/100, pero el STM32H563ZI queda a 3,8 puntos y el STM32U5A5ZJ a 6,7: por mi propio criterio, menos de 5 puntos es un empate técnico. Lo que separa al H743 es un solo criterio, la FPU de doble precisión, que vale el 23,8 %. Si trabajo en marco local ENU con float, que es lo que tengo calculado en la hoja Requisitos, ese criterio se neutraliza y el H563 gana en consumo, en temperatura y en riesgo de calendario. Mi desempate declarado es el marco de referencia, y es una decisión de software, no de catálogo.»
A26: Por qué estas notas (resumen; el detalle de cada ancla está en la hoja Escala)
A27: Margen de cálculo del filtro | B27: Los diez van sobrados: 16,2 Mciclos/s son entre el 3,4 % de un H743 a 480 MHz y el 20 % de un L476 a 80 MHz. Todos por debajo del 25 % del ancla del 3. Les pongo 4 y no 5 a todos porque es cálculo, no medida en placa. Nota igual para los diez, así que este criterio no decide: es justo la conclusión que quiero enseñar, los MHz no distinguen entre ellos.
A28: Precisión numérica y marco de referencia | B28: Solo 56 de las 337 referencias que pasan mi filtro tienen FPU de doble precisión, y están únicamente en las series H7 y F7. El H743 y el F767 se llevan el 5; los otros ocho se quedan en 3, que es el ancla de float con marco local ENU y el cálculo de resolución hecho. Este es el criterio que decide.
A29: Margen de periféricos y patillas | B29: Casi todos se quedan con 3 SPI frente a los 3 que pido: margen cero. Los que además solo tienen 1 CAN o 2 I2C bajan a 1. Los tres de LQFP144 con 6 SPI (F767, H743, H563) se llevan un 4, y no un 5 porque todavía no los he rutado enteros en CubeMX.
A30: Arquitectura y ancho de banda del registro | B30: Nota 5 a los que tienen interfaz dedicada y SD/MMC además de la memoria externa. Bajan a 4 el G474, el U5A5 y el C5A3, que tienen QUADSPI u Octo SPI pero no SD/MMC, así que me dejan una sola vía para los 18,4 MB.
A31: Consumo durante la espera en rampa | B31: Con los µA/MHz en modo run del catálogo de ST, cada uno a su reloj máximo: U385 1,3 mA · U5A5 4,2 · L476 8 · L552 y C5A3 unos 11 · H563 28 · F446 30 · F767 91 · H743 130. Aquí el H743 es el peor con diferencia y las series de bajo consumo barren. ST no publica el consumo del G474RE en el selector, así que le pongo 3 aplicando mi propia regla de quedarme con la nota baja cuando dudo, y anoto que está pendiente de sacarlo de la ficha.
A32: Funciones de robustez | B32: Según AN5342 de ST, solo las series H5, H7, U3, U5 y C5 llevan ECC en memorias internas. H743, H563 y U5A5 se llevan el 5: ECC en Flash y en RAM, más watchdog con ventana, CSS y detector de caída de tensión. El G474, el U385 y el C5A3 se quedan en 4 porque su ECC cubre la Flash y solo una parte de la SRAM. F446, F767, L476 y L552 no llevan ECC: watchdog y CSS, que es el ancla del 3. Que el F767 sea Cortex-M7 no le da ECC, y esa es justo la confusión que quiero evitar.
A33: Continuidad con el equipo y ecosistema | B33: Pongo 3 a los diez porque todavía no sé qué vuela hoy Faraday. Con la misma nota este criterio no decide, y en cuanto lo confirme con Víctor lo actualizo y vuelvo a mirar la sensibilidad.
A34: Riesgo de calendario | B34: Los M4 arrancan desde CubeMX sin tocar nada, nota 5. Los M33 maduros (H563, L552, U5A5) van a 4. El U385 baja a 3 y el C5A3 a 2 por ser series de 2025 y 2026 con menos ejemplos y menos rodaje. El H743 y el F767 se quedan en 2: caché, MPU y coherencia de DMA por resolver, y con una semana por delante eso es riesgo real.
A35: Coste y disponibilidad real | B35: Orden aproximado: U385 y G474 en torno a 5-7 €, F446 y L476 sobre 8-9 €, L552 y H563 sobre 10-12 €, F767 y U5A5 sobre 15 €, H743 sobre 18 € con el precedente de escasez de 2021, y el C5A3 con plazo todavía incierto por ser serie nueva. Pendiente de confirmar en Mouser o Farnell el día que lo pida.
A36: Lo que me queda por convertir en dato medido | B36: Las notas de cálculo y de consumo son estimaciones a partir de la ficha y del catálogo paramétrico. En cuanto tenga la Nucleo, mido los ciclos del filtro con el contador DWT y la corriente media en rampa, y sustituyo las dos. Con menos de 5 puntos entre el primero y el segundo, esas dos medidas pueden cambiar el orden.

Sheet Sensibilidad
A1: Paso 6 — ¿La decisión depende de mis pesos?
A2: Este es el paso que convierte mi opinión en una decisión defendible. Recalculo todo con los pesos igualados y quitando un criterio cada vez. Si gana el mismo en todos los escenarios, los pesos dan igual y la elección se sostiene sola.
A4: Escenario | B4: STM32F411RE | C4: STM32F446RE | D4: STM32G474RE | E4: STM32H743ZI | F4: ESP32-S3 | G4: STM32F767ZI | H4: STM32H563ZI | I4: STM32L476RG | J4: STM32L552ZE | K4: STM32U385RG | L4: STM32U5A5ZJ | M4: STM32C5A3ZG | N4: Ganador
A5: Pesos del análisis (base) | B5: =Matriz!C17 | C5: =Matriz!D17 -> 70.238095 | D5: =Matriz!E17 -> 72.142857 | E5: =Matriz!F17 -> 86.190476 | F5: =Matriz!G17 | G5: =Matriz!H17 -> 76.190476 | H5: =Matriz!I17 -> 82.380952 | I5: =Matriz!J17 -> 71.428571 | ... M5: =Matriz!N17 -> 72.142857 | N5: =IFERROR(INDEX($B$4:$M$4,MATCH(MAX($B5:$M5),$B5:$M5,0)),"—") -> STM32H743ZI
A6: Todos los pesos iguales | B6: =IF(ISNUMBER(Matriz!C17),AVERAGE(Matriz!C5:C13)/5*100,"") | C6: =IF(ISNUMBER(Matriz!D17),AVERAGE(Matriz!D5:D13)/5*100,"") -> 75.555556 | D6: =IF(ISNUMBER(Matriz!E17),AVERAGE(Matriz!E5:E13)/5*100,"") -> 73.333333 | E6: =IF(ISNUMBER(Matriz!F17),AVERAGE(Matriz!F5:F13)/5*100,"") -> 73.333333 | F6: =IF(ISNUMBER(Matriz!G17),AVERAGE(Matriz!G5:G13)/5*100,"") | G6: =IF(ISNUMBER(Matriz!H17),AVERAGE(Matriz!H5:H13)/5*100,"") -> 71.111111 | H6: =IF(ISNUMBER(Matriz!I17),AVERAGE(Matriz!I5:I13)/5*100,"") -> 80 | I6: =IF(ISNUMBER(Matriz!J17),AVERAGE(Matriz!J5:J13)/5*100,"") -> 75.555556 | ... M6: =IF(ISNUMBER(Matriz!N17),AVERAGE(Matriz!N5:N13)/5*100,"") -> 64.444444 | N6: =IFERROR(INDEX($B$4:$M$4,MATCH(MAX($B6:$M6),$B6:$M6,0)),"—") -> STM32H563ZI
A7: Sin el criterio: Margen de cálculo del filtro | B7: =IF(ISNUMBER(Matriz!C17),(SUMPRODUCT(Matriz!$B$5:$B$13,Matriz!C5:C13)-Matriz!$B$5*Matriz!C5)/(100-Matriz!$B$5)*20,"") | C7: =IF(ISNUMBER(Matriz!D17),(SUMPRODUCT(Matriz!$B$5:$B$13,Matriz!D5:D13)-Matriz!$B$5*Matriz!D5)/(100-Matriz!$B$5)*20,"") -> 68.918919 | D7: =IF(ISNUMBER(Matriz!E17),(SUMPRODUCT(Matriz!$B$5:$B$13,Matriz!E5:E13)-Matriz!$B$5*Matriz!E5)/(100-Matriz!$B$5)*20,"") -> 71.081081 | E7: =IF(ISNUMBER(Matriz!F17),(SUMPRODUCT(Matriz!$B$5:$B$13,Matriz!F5:F13)-Matriz!$B$5*Matriz!F5)/(100-Matriz!$B$5)*20,"") -> 87.027027 | F7: =IF(ISNUMBER(Matriz!G17),(SUMPRODUCT(Matriz!$B$5:$B$13,Matriz!G5:G13)-Matriz!$B$5*Matriz!G5)/(100-Matriz!$B$5)*20,"") | G7: =IF(ISNUMBER(Matriz!H17),(SUMPRODUCT(Matriz!$B$5:$B$13,Matriz!H5:H13)-Matriz!$B$5*Matriz!H5)/(100-Matriz!$B$5)*20,"") -> 75.675676 | H7: =IF(ISNUMBER(Matriz!I17),(SUMPRODUCT(Matriz!$B$5:$B$13,Matriz!I5:I13)-Matriz!$B$5*Matriz!I5)/(100-Matriz!$B$5)*20,"") -> 82.702703 | I7: =IF(ISNUMBER(Matriz!J17),(SUMPRODUCT(Matriz!$B$5:$B$13,Matriz!J5:J13)-Matriz!$B$5*Matriz!J5)/(100-Matriz!$B$5)*20,"") -> 70.27027 | ... M7: =IF(ISNUMBER(Matriz!N17),(SUMPRODUCT(Matriz!$B$5:$B$13,Matriz!N5:N13)-Matriz!$B$5*Matriz!N5)/(100-Matriz!$B$5)*20,"") -> 71.081081 | N7: =IFERROR(INDEX($B$4:$M$4,MATCH(MAX($B7:$M7),$B7:$M7,0)),"—") -> STM32H743ZI
A8: Sin el criterio: Precisión numérica y marco de referencia | B8: =IF(ISNUMBER(Matriz!C17),(SUMPRODUCT(Matriz!$B$5:$B$13,Matriz!C5:C13)-Matriz!$B$6*Matriz!C6)/(100-Matriz!$B$6)*20,"") | C8: =IF(ISNUMBER(Matriz!D17),(SUMPRODUCT(Matriz!$B$5:$B$13,Matriz!D5:D13)-Matriz!$B$6*Matriz!D6)/(100-Matriz!$B$6)*20,"") -> 73.4375 | D8: =IF(ISNUMBER(Matriz!E17),(SUMPRODUCT(Matriz!$B$5:$B$13,Matriz!E5:E13)-Matriz!$B$6*Matriz!E6)/(100-Matriz!$B$6)*20,"") -> 75.9375 | E8: =IF(ISNUMBER(Matriz!F17),(SUMPRODUCT(Matriz!$B$5:$B$13,Matriz!F5:F13)-Matriz!$B$6*Matriz!F6)/(100-Matriz!$B$6)*20,"") -> 81.875 | F8: =IF(ISNUMBER(Matriz!G17),(SUMPRODUCT(Matriz!$B$5:$B$13,Matriz!G5:G13)-Matriz!$B$6*Matriz!G6)/(100-Matriz!$B$6)*20,"") | G8: =IF(ISNUMBER(Matriz!H17),(SUMPRODUCT(Matriz!$B$5:$B$13,Matriz!H5:H13)-Matriz!$B$6*Matriz!H6)/(100-Matriz!$B$6)*20,"") -> 68.75 | H8: =IF(ISNUMBER(Matriz!I17),(SUMPRODUCT(Matriz!$B$5:$B$13,Matriz!I5:I13)-Matriz!$B$6*Matriz!I6)/(100-Matriz!$B$6)*20,"") -> 89.375 | I8: =IF(ISNUMBER(Matriz!J17),(SUMPRODUCT(Matriz!$B$5:$B$13,Matriz!J5:J13)-Matriz!$B$6*Matriz!J6)/(100-Matriz!$B$6)*20,"") -> 75 | ... M8: =IF(ISNUMBER(Matriz!N17),(SUMPRODUCT(Matriz!$B$5:$B$13,Matriz!N5:N13)-Matriz!$B$6*Matriz!N6)/(100-Matriz!$B$6)*20,"") -> 75.9375 | N8: =IFERROR(INDEX($B$4:$M$4,MATCH(MAX($B8:$M8),$B8:$M8,0)),"—") -> STM32H563ZI
A9: Sin el criterio: Margen de periféricos y patillas | B9: =IF(ISNUMBER(Matriz!C17),(SUMPRODUCT(Matriz!$B$5:$B$13,Matriz!C5:C13)-Matriz!$B$7*Matriz!C7)/(100-Matriz!$B$7)*20,"") | C9: =IF(ISNUMBER(Matriz!D17),(SUMPRODUCT(Matriz!$B$5:$B$13,Matriz!D5:D13)-Matriz!$B$7*Matriz!D7)/(100-Matriz!$B$7)*20,"") -> 71.358025 | D9: =IF(ISNUMBER(Matriz!E17),(SUMPRODUCT(Matriz!$B$5:$B$13,Matriz!E5:E13)-Matriz!$B$7*Matriz!E7)/(100-Matriz!$B$7)*20,"") -> 73.333333 | E9: =IF(ISNUMBER(Matriz!F17),(SUMPRODUCT(Matriz!$B$5:$B$13,Matriz!F5:F13)-Matriz!$B$7*Matriz!F7)/(100-Matriz!$B$7)*20,"") -> 86.419753 | F9: =IF(ISNUMBER(Matriz!G17),(SUMPRODUCT(Matriz!$B$5:$B$13,Matriz!G5:G13)-Matriz!$B$7*Matriz!G7)/(100-Matriz!$B$7)*20,"") | G9: =IF(ISNUMBER(Matriz!H17),(SUMPRODUCT(Matriz!$B$5:$B$13,Matriz!H5:H13)-Matriz!$B$7*Matriz!H7)/(100-Matriz!$B$7)*20,"") -> 76.049383 | H9: =IF(ISNUMBER(Matriz!I17),(SUMPRODUCT(Matriz!$B$5:$B$13,Matriz!I5:I13)-Matriz!$B$7*Matriz!I7)/(100-Matriz!$B$7)*20,"") -> 82.469136 | I9: =IF(ISNUMBER(Matriz!J17),(SUMPRODUCT(Matriz!$B$5:$B$13,Matriz!J5:J13)-Matriz!$B$7*Matriz!J7)/(100-Matriz!$B$7)*20,"") -> 73.333333 | ... M9: =IF(ISNUMBER(Matriz!N17),(SUMPRODUCT(Matriz!$B$5:$B$13,Matriz!N5:N13)-Matriz!$B$7*Matriz!N7)/(100-Matriz!$B$7)*20,"") -> 74.074074 | N9: =IFERROR(INDEX($B$4:$M$4,MATCH(MAX($B9:$M9),$B9:$M9,0)),"—") -> STM32H743ZI
A10: Sin el criterio: Arquitectura y ancho de banda del registro | B10: =IF(ISNUMBER(Matriz!C17),(SUMPRODUCT(Matriz!$B$5:$B$13,Matriz!C5:C13)-Matriz!$B$8*Matriz!C8)/(100-Matriz!$B$8)*20,"") | C10: =IF(ISNUMBER(Matriz!D17),(SUMPRODUCT(Matriz!$B$5:$B$13,Matriz!D5:D13)-Matriz!$B$8*Matriz!D8)/(100-Matriz!$B$8)*20,"") -> 66.666667 | D10: =IF(ISNUMBER(Matriz!E17),(SUMPRODUCT(Matriz!$B$5:$B$13,Matriz!E5:E13)-Matriz!$B$8*Matriz!E8)/(100-Matriz!$B$8)*20,"") -> 71.2 | E10: =IF(ISNUMBER(Matriz!F17),(SUMPRODUCT(Matriz!$B$5:$B$13,Matriz!F5:F13)-Matriz!$B$8*Matriz!F8)/(100-Matriz!$B$8)*20,"") -> 84.533333 | F10: =IF(ISNUMBER(Matriz!G17),(SUMPRODUCT(Matriz!$B$5:$B$13,Matriz!G5:G13)-Matriz!$B$8*Matriz!G8)/(100-Matriz!$B$8)*20,"") | G10: =IF(ISNUMBER(Matriz!H17),(SUMPRODUCT(Matriz!$B$5:$B$13,Matriz!H5:H13)-Matriz!$B$8*Matriz!H8)/(100-Matriz!$B$8)*20,"") -> 73.333333 | H10: =IF(ISNUMBER(Matriz!I17),(SUMPRODUCT(Matriz!$B$5:$B$13,Matriz!I5:I13)-Matriz!$B$8*Matriz!I8)/(100-Matriz!$B$8)*20,"") -> 80.266667 | I10: =IF(ISNUMBER(Matriz!J17),(SUMPRODUCT(Matriz!$B$5:$B$13,Matriz!J5:J13)-Matriz!$B$8*Matriz!J8)/(100-Matriz!$B$8)*20,"") -> 68 | ... M10: =IF(ISNUMBER(Matriz!N17),(SUMPRODUCT(Matriz!$B$5:$B$13,Matriz!N5:N13)-Matriz!$B$8*Matriz!N8)/(100-Matriz!$B$8)*20,"") -> 71.2 | N10: =IFERROR(INDEX($B$4:$M$4,MATCH(MAX($B10:$M10),$B10:$M10,0)),"—") -> STM32H743ZI
A11: Sin el criterio: Consumo durante la espera en rampa | B11: =IF(ISNUMBER(Matriz!C17),(SUMPRODUCT(Matriz!$B$5:$B$13,Matriz!C5:C13)-Matriz!$B$9*Matriz!C9)/(100-Matriz!$B$9)*20,"") | C11: =IF(ISNUMBER(Matriz!D17),(SUMPRODUCT(Matriz!$B$5:$B$13,Matriz!D5:D13)-Matriz!$B$9*Matriz!D9)/(100-Matriz!$B$9)*20,"") -> 69.210526 | D11: =IF(ISNUMBER(Matriz!E17),(SUMPRODUCT(Matriz!$B$5:$B$13,Matriz!E5:E13)-Matriz!$B$9*Matriz!E9)/(100-Matriz!$B$9)*20,"") -> 73.421053 | E11: =IF(ISNUMBER(Matriz!F17),(SUMPRODUCT(Matriz!$B$5:$B$13,Matriz!F5:F13)-Matriz!$B$9*Matriz!F9)/(100-Matriz!$B$9)*20,"") -> 91.052632 | F11: =IF(ISNUMBER(Matriz!G17),(SUMPRODUCT(Matriz!$B$5:$B$13,Matriz!G5:G13)-Matriz!$B$9*Matriz!G9)/(100-Matriz!$B$9)*20,"") | G11: =IF(ISNUMBER(Matriz!H17),(SUMPRODUCT(Matriz!$B$5:$B$13,Matriz!H5:H13)-Matriz!$B$9*Matriz!H9)/(100-Matriz!$B$9)*20,"") -> 77.894737 | H11: =IF(ISNUMBER(Matriz!I17),(SUMPRODUCT(Matriz!$B$5:$B$13,Matriz!I5:I13)-Matriz!$B$9*Matriz!I9)/(100-Matriz!$B$9)*20,"") -> 82.631579 | I11: =IF(ISNUMBER(Matriz!J17),(SUMPRODUCT(Matriz!$B$5:$B$13,Matriz!J5:J13)-Matriz!$B$9*Matriz!J9)/(100-Matriz!$B$9)*20,"") -> 68.421053 | ... M11: =IF(ISNUMBER(Matriz!N17),(SUMPRODUCT(Matriz!$B$5:$B$13,Matriz!N5:N13)-Matriz!$B$9*Matriz!N9)/(100-Matriz!$B$9)*20,"") -> 69.210526 | N11: =IFERROR(INDEX($B$4:$M$4,MATCH(MAX($B11:$M11),$B11:$M11,0)),"—") -> STM32H743ZI
A12: Sin el criterio: Funciones de robustez | B12: =IF(ISNUMBER(Matriz!C17),(SUMPRODUCT(Matriz!$B$5:$B$13,Matriz!C5:C13)-Matriz!$B$10*Matriz!C10)/(100-Matriz!$B$10)*20,"") | C12: =IF(ISNUMBER(Matriz!D17),(SUMPRODUCT(Matriz!$B$5:$B$13,Matriz!D5:D13)-Matriz!$B$10*Matriz!D10)/(100-Matriz!$B$10)*20,"") -> 74.576271 | D12: =IF(ISNUMBER(Matriz!E17),(SUMPRODUCT(Matriz!$B$5:$B$13,Matriz!E5:E13)-Matriz!$B$10*Matriz!E10)/(100-Matriz!$B$10)*20,"") -> 68.813559 | E12: =IF(ISNUMBER(Matriz!F17),(SUMPRODUCT(Matriz!$B$5:$B$13,Matriz!F5:F13)-Matriz!$B$10*Matriz!F10)/(100-Matriz!$B$10)*20,"") -> 80.338983 | F12: =IF(ISNUMBER(Matriz!G17),(SUMPRODUCT(Matriz!$B$5:$B$13,Matriz!G5:G13)-Matriz!$B$10*Matriz!G10)/(100-Matriz!$B$10)*20,"") | G12: =IF(ISNUMBER(Matriz!H17),(SUMPRODUCT(Matriz!$B$5:$B$13,Matriz!H5:H13)-Matriz!$B$10*Matriz!H10)/(100-Matriz!$B$10)*20,"") -> 83.050847 | H12: =IF(ISNUMBER(Matriz!I17),(SUMPRODUCT(Matriz!$B$5:$B$13,Matriz!I5:I13)-Matriz!$B$10*Matriz!I10)/(100-Matriz!$B$10)*20,"") -> 74.915254 | I12: =IF(ISNUMBER(Matriz!J17),(SUMPRODUCT(Matriz!$B$5:$B$13,Matriz!J5:J13)-Matriz!$B$10*Matriz!J10)/(100-Matriz!$B$10)*20,"") -> 76.271186 | ... M12: =IF(ISNUMBER(Matriz!N17),(SUMPRODUCT(Matriz!$B$5:$B$13,Matriz!N5:N13)-Matriz!$B$10*Matriz!N10)/(100-Matriz!$B$10)*20,"") -> 68.813559 | N12: =IFERROR(INDEX($B$4:$M$4,MATCH(MAX($B12:$M12),$B12:$M12,0)),"—") -> STM32F767ZI
A13: Sin el criterio: Continuidad con el equipo y ecosistema | B13: =IF(ISNUMBER(Matriz!C17),(SUMPRODUCT(Matriz!$B$5:$B$13,Matriz!C5:C13)-Matriz!$B$11*Matriz!C11)/(100-Matriz!$B$11)*20,"") | C13: =IF(ISNUMBER(Matriz!D17),(SUMPRODUCT(Matriz!$B$5:$B$13,Matriz!D5:D13)-Matriz!$B$11*Matriz!D11)/(100-Matriz!$B$11)*20,"") -> 70.75 | D13: =IF(ISNUMBER(Matriz!E17),(SUMPRODUCT(Matriz!$B$5:$B$13,Matriz!E5:E13)-Matriz!$B$11*Matriz!E11)/(100-Matriz!$B$11)*20,"") -> 72.75 | E13: =IF(ISNUMBER(Matriz!F17),(SUMPRODUCT(Matriz!$B$5:$B$13,Matriz!F5:F13)-Matriz!$B$11*Matriz!F11)/(100-Matriz!$B$11)*20,"") -> 87.5 | F13: =IF(ISNUMBER(Matriz!G17),(SUMPRODUCT(Matriz!$B$5:$B$13,Matriz!G5:G13)-Matriz!$B$11*Matriz!G11)/(100-Matriz!$B$11)*20,"") | G13: =IF(ISNUMBER(Matriz!H17),(SUMPRODUCT(Matriz!$B$5:$B$13,Matriz!H5:H13)-Matriz!$B$11*Matriz!H11)/(100-Matriz!$B$11)*20,"") -> 77 | H13: =IF(ISNUMBER(Matriz!I17),(SUMPRODUCT(Matriz!$B$5:$B$13,Matriz!I5:I13)-Matriz!$B$11*Matriz!I11)/(100-Matriz!$B$11)*20,"") -> 83.5 | I13: =IF(ISNUMBER(Matriz!J17),(SUMPRODUCT(Matriz!$B$5:$B$13,Matriz!J5:J13)-Matriz!$B$11*Matriz!J11)/(100-Matriz!$B$11)*20,"") -> 72 | ... M13: =IF(ISNUMBER(Matriz!N17),(SUMPRODUCT(Matriz!$B$5:$B$13,Matriz!N5:N13)-Matriz!$B$11*Matriz!N11)/(100-Matriz!$B$11)*20,"") -> 72.75 | N13: =IFERROR(INDEX($B$4:$M$4,MATCH(MAX($B13:$M13),$B13:$M13,0)),"—") -> STM32H743ZI
A14: Sin el criterio: Riesgo de calendario | B14: =IF(ISNUMBER(Matriz!C17),(SUMPRODUCT(Matriz!$B$5:$B$13,Matriz!C5:C13)-Matriz!$B$12*Matriz!C12)/(100-Matriz!$B$12)*20,"") | C14: =IF(ISNUMBER(Matriz!D17),(SUMPRODUCT(Matriz!$B$5:$B$13,Matriz!D5:D13)-Matriz!$B$12*Matriz!D12)/(100-Matriz!$B$12)*20,"") -> 69.135802 | D14: =IF(ISNUMBER(Matriz!E17),(SUMPRODUCT(Matriz!$B$5:$B$13,Matriz!E5:E13)-Matriz!$B$12*Matriz!E12)/(100-Matriz!$B$12)*20,"") -> 71.111111 | E14: =IF(ISNUMBER(Matriz!F17),(SUMPRODUCT(Matriz!$B$5:$B$13,Matriz!F5:F13)-Matriz!$B$12*Matriz!F12)/(100-Matriz!$B$12)*20,"") -> 87.901235 | F14: =IF(ISNUMBER(Matriz!G17),(SUMPRODUCT(Matriz!$B$5:$B$13,Matriz!G5:G13)-Matriz!$B$12*Matriz!G12)/(100-Matriz!$B$12)*20,"") | G14: =IF(ISNUMBER(Matriz!H17),(SUMPRODUCT(Matriz!$B$5:$B$13,Matriz!H5:H13)-Matriz!$B$12*Matriz!H12)/(100-Matriz!$B$12)*20,"") -> 77.530864 | H14: =IF(ISNUMBER(Matriz!I17),(SUMPRODUCT(Matriz!$B$5:$B$13,Matriz!I5:I13)-Matriz!$B$12*Matriz!I12)/(100-Matriz!$B$12)*20,"") -> 82.469136 | I14: =IF(ISNUMBER(Matriz!J17),(SUMPRODUCT(Matriz!$B$5:$B$13,Matriz!J5:J13)-Matriz!$B$12*Matriz!J12)/(100-Matriz!$B$12)*20,"") -> 70.37037 | ... M14: =IF(ISNUMBER(Matriz!N17),(SUMPRODUCT(Matriz!$B$5:$B$13,Matriz!N5:N13)-Matriz!$B$12*Matriz!N12)/(100-Matriz!$B$12)*20,"") -> 73.333333 | N14: =IFERROR(INDEX($B$4:$M$4,MATCH(MAX($B14:$M14),$B14:$M14,0)),"—") -> STM32H743ZI
A15: Sin el criterio: Coste y disponibilidad real | B15: =IF(ISNUMBER(Matriz!C17),(SUMPRODUCT(Matriz!$B$5:$B$13,Matriz!C5:C13)-Matriz!$B$13*Matriz!C13)/(100-Matriz!$B$13)*20,"") | C15: =IF(ISNUMBER(Matriz!D17),(SUMPRODUCT(Matriz!$B$5:$B$13,Matriz!D5:D13)-Matriz!$B$13*Matriz!D13)/(100-Matriz!$B$13)*20,"") -> 69.512195 | D15: =IF(ISNUMBER(Matriz!E17),(SUMPRODUCT(Matriz!$B$5:$B$13,Matriz!E5:E13)-Matriz!$B$13*Matriz!E13)/(100-Matriz!$B$13)*20,"") -> 71.463415 | E15: =IF(ISNUMBER(Matriz!F17),(SUMPRODUCT(Matriz!$B$5:$B$13,Matriz!F5:F13)-Matriz!$B$13*Matriz!F13)/(100-Matriz!$B$13)*20,"") -> 86.829268 | F15: =IF(ISNUMBER(Matriz!G17),(SUMPRODUCT(Matriz!$B$5:$B$13,Matriz!G5:G13)-Matriz!$B$13*Matriz!G13)/(100-Matriz!$B$13)*20,"") | G15: =IF(ISNUMBER(Matriz!H17),(SUMPRODUCT(Matriz!$B$5:$B$13,Matriz!H5:H13)-Matriz!$B$13*Matriz!H13)/(100-Matriz!$B$13)*20,"") -> 76.585366 | H15: =IF(ISNUMBER(Matriz!I17),(SUMPRODUCT(Matriz!$B$5:$B$13,Matriz!I5:I13)-Matriz!$B$13*Matriz!I13)/(100-Matriz!$B$13)*20,"") -> 82.439024 | I15: =IF(ISNUMBER(Matriz!J17),(SUMPRODUCT(Matriz!$B$5:$B$13,Matriz!J5:J13)-Matriz!$B$13*Matriz!J13)/(100-Matriz!$B$13)*20,"") -> 70.731707 | ... M15: =IF(ISNUMBER(Matriz!N17),(SUMPRODUCT(Matriz!$B$5:$B$13,Matriz!N5:N13)-Matriz!$B$13*Matriz!N13)/(100-Matriz!$B$13)*20,"") -> 72.439024 | N15: =IFERROR(INDEX($B$4:$M$4,MATCH(MAX($B15:$M15),$B15:$M15,0)),"—") -> STM32H743ZI
